Workbook

Sheet French Project
A1: Onshore Budget | H1: Offshore Budget | N1: Paramètres
A2: Phase | B2: Level | C2: Task code | D2: Description | E2: Indicative Budget | F2: Real Budget | H2: Task code | I2: Description | J2: Indicative Budget | K2: Real Budget | N2: Global Budget with PPR | P2: =P4+P14+P16 -> 0
A3: Upstream | B3: Project | N3: Global Budget without PPR | P3: =P2*0.9 -> 0
B4: Project | N4: Global Budget with PPR (Abacus ; sold to CAAGIS) | P4: 0
B5: Project | N5: Global Budget without PPR | P5: =P4*90% -> 0
B6: Project | C6: xF105 | D6: Fr - SFD Acceptance | E6: =($P$4+$P$6)*('Int. Budget On-Off 1'!$D$14+'Int. Budget On-Off 1'!$D$15+'Int. Budget On-Off 1'!$D$16+'Int. Budget On-Off 1'!$D$17+'Int. Budget On-Off 1'!$D$18) -> 0 | N6: Pre-integration budget to extract (negative) | P6: =-P10 -> 0
B7: Project | N7: Global budget after Pre-integration budget | P7: =P5+P6 -> 0
B8: Project | C8: xF110 | D8: Fr - Doing development sheet | E8: =($P$4+$P$6)*'Int. Budget On-Off 1'!$D$19 -> 0
B9: Project
B10: Project | N10: Fr - Pre-intergration (xnet) - PPR include | P10: 0
B11: Project | C11: xF121 | D11: Fr - SMT Acceptance | E11: =($P$4+$P$6)*('Int. Budget On-Off 1'!$D$23+'Int. Budget On-Off 1'!$D$24+'Int. Budget On-Off 1'!$D$26) -> 0
B12: Project
B13: Project | C13: xF145 | D13: Fr - Param Acceptance | E13: =($P$4+$P$6)*'Int. Budget On-Off 1'!$D$25 -> 0
A14: Development | B14: Project | N14: Budget for Additional qualification test plan with PPR | P14: 0
B15: Project | C15: xF3** | D15: Fr - CUT | E15: =($P$4+$P$6)*('Int. Budget On-Off 1'!$D$22+'Int. Budget On-Off 1'!$D$21) -> 0 | F15: ='Development effort'!F24 -> 0
B16: Project | N16: Budget for acceptance testing changes with PPR | P16: 0
A17: Qualification | B17: Project | C17: xF500 | D17: Fr - Qualification | E17: =(($P$4+$P$6)*'Int. Budget On-Off 1'!$D$27+P$14*0.9*0.9)*70% -> 0
B18: Project
B19: Project | C19: xF501 | D19: Fr - Qualification defect fixing | E19: =(($P$4+$P$6)*'Int. Budget On-Off 1'!$D$27+P$14*0.9*0.9)*30% -> 0
A20: Documentation | B20: Project | C20: xF160 | D20: Fr - Documentation | E20: =($P$4+$P$6)*'Int. Budget On-Off 1'!$D$30 -> 0 | F20: ='Development effort'!E23 -> 0
A21: Management | B21: Project | C21: xF130 | D21: Fr - Project Leader | E21: =($P$4+$P$6)*'Int. Budget On-Off 1'!$D$35 -> 0
A22: Pré-intégration | B22: Project | C22: xF600 | D22: Fr - Pre-intergration (xnet) | E22: =-$P$6*0.9 -> 0
A23: Acceptance testing | B23: Project | C23: xF700 | D23: Fr - Acceptance testing (Analyse) | E23: =(($P$4+$P$6)*'Int. Budget On-Off 1'!$D$29+P$16*0.9*0.9)*50% -> 0
B24: Project
B25: Project | C25: xF701 | D25: Fr - Acceptance testing (Bug) | E25: =(($P$4+$P$6)*'Int. Budget On-Off 1'!$D$29+P$16*0.9*0.9)*50% -> 0
B26: Project | C26: xF702 | D26: Fr - Acceptance testing (changes)
A28: Transversal | B28: Version | D28: Global Project Manager | E28: =($P$4+$P$6)*('Int. Budget On-Off 1'!$D$31+'Int. Budget On-Off 1'!$D$32+'Int. Budget On-Off 1'!$D$33)*26% -> 0 | F28: =E28 -> 0
B29: Version | D29: Project Manager | E29: =($P$4+$P$6)*('Int. Budget On-Off 1'!$D$31+'Int. Budget On-Off 1'!$D$32+'Int. Budget On-Off 1'!$D$33)*51.5%+(P$14+P$16)*0.9*0.1 -> 0 | F29: =E29 -> 0
B30: Version
B31: Version | D31: Test Manager | E31: =($P$4+$P$6)*'Int. Budget On-Off 1'!$D$34 -> 0 | F31: =E31 -> 0
B32: Version | D32: Deployment | E32: =($P$4+$P$6)*'Int. Budget On-Off 1'!$D$37 -> 0 | F32: =E32 -> 0
B33: Version | D33: Technical Support | E33: =($P$4+$P$6)*('Int. Budget On-Off 1'!$D$31+'Int. Budget On-Off 1'!$D$32+'Int. Budget On-Off 1'!$D$33)*22.5% -> 0 | F33: =E33 -> 0
D34: TOTAL | E34: =SUM(E3:E33) -> 0 | F34: =SUM(F3:F33) -> 0 | I34: TOTAL | J34: =SUM(J3:J33) -> 0 | K34: =SUM(K3:K33) -> 0
D35: Controle Transversal (somme above) | E35: =SUM(E28:E33) -> 0
A38: TOTAL Onshore + Offshore | E38: =E34+J34 -> 0 | F38: =F34+K34 -> 0
D39: Contrôle (Internal Bubget) | E39: =P3 -> 0

Sheet Indian Project
A2: Onshore Budget | I2: Offshore Budget | P2: Paramètres
A3: Phase | B3: Level | C3: Task code | D3: Description | E3: Solded Budget | F3: Indicative Budget | G3: Real Budget | I3: Task code | J3: Description | K3: Solded Budget | L3: Indicative Budget | M3: Real Budget | P3: Project Type 1 : Offshore involves from SFDI Acceptance 2 : Offshore involves from Dev Sheet creation 3 : Offshore involves from CUT | R3: 1
A4: Upstream | B4: Project | C4: xF10A | D4: Fr - Upstream Assistance | E4: =IF($R$3=1,INDEX('Int. Budget On-Off 1'!$AC$12:$AF$34,MATCH('Indian Project'!$C4,'Int. Budget On-Off 1'!$AC$12:$AC$34,0),3),IF($R$3=2,INDEX('Int. Budget On-Off 2'!$AC$12:$AF$34,MATCH('Indian Project'!$C4,'Int. Budget On-Off 2'!$AC$12:$AC$34,0),3),IF($R$3=3,INDEX('Int. Budget On-Off 3'!$AC$12:$AF$34,MATCH('Indian Project'!$C4,'Int. Budget On-Off 3'!$AC$12:$AC$34,0),3)))) -> 0 | F4: =IF($R$3=1,INDEX('Int. Budget On-Off 1'!$AC$12:$AF$34,MATCH('Indian Project'!$C4,'Int. Budget On-Off 1'!$AC$12:$AC$34,0),4),IF($R$3=2,INDEX('Int. Budget On-Off 2'!$AC$12:$AF$34,MATCH('Indian Project'!$C4,'Int. Budget On-Off 2'!$AC$12:$AC$34,0),4),IF($R$3=3,INDEX('Int. Budget On-Off 3'!$AC$12:$AF$34,MATCH('Indian Project'!$C4,'Int. Budget On-Off 3'!$AC$12:$AC$34,0),4)))) -> 0 | I4: xI101 | J4: In - Project presentation | K4: =IF($R$3=1,INDEX('Int. Budget On-Off 1'!$AG$12:$AJ$34,MATCH('Indian Project'!$I4,'Int. Budget On-Off 1'!$AG$12:$AG$34,0),3),IF($R$3=2,INDEX('Int. Budget On-Off 2'!$AG$12:$AJ$34,MATCH('Indian Project'!$I4,'Int. Budget On-Off 2'!$AG$12:$AG$34,0),3),IF($R$3=3,INDEX('Int. Budget On-Off 3'!$AG$12:$AJ$34,MATCH('Indian Project'!$I4,'Int. Budget On-Off 3'!$AG$12:$AG$34,0),3)))) -> 0 | L4: =IF($R$3=1,INDEX('Int. Budget On-Off 1'!$AG$12:$AJ$34,MATCH('Indian Project'!$I4,'Int. Budget On-Off 1'!$AG$12:$AG$34,0),4),IF($R$3=2,INDEX('Int. Budget On-Off 2'!$AG$12:$AJ$34,MATCH('Indian Project'!$I4,'Int. Budget On-Off 2'!$AG$12:$AG$34,0),4),IF($R$3=3,INDEX('Int. Budget On-Off 3'!$AG$12:$AJ$34,MATCH('Indian Project'!$I4,'Int. Budget On-Off 3'!$AG$12:$AG$34,0),4)))) -> 0 | P4: Global Budget with PPR | R4: =R6+R16+R18 -> 0
B5: Project | C5: xF10T | D5: Fr - Upstream Other Tasks + Transl. | E5: =IF($R$3=1,INDEX('Int. Budget On-Off 1'!$AC$12:$AF$34,MATCH('Indian Project'!$C5,'Int. Budget On-Off 1'!$AC$12:$AC$34,0),3),IF($R$3=2,INDEX('Int. Budget On-Off 2'!$AC$12:$AF$34,MATCH('Indian Project'!$C5,'Int. Budget On-Off 2'!$AC$12:$AC$34,0),3),IF($R$3=3,INDEX('Int. Budget On-Off 3'!$AC$12:$AF$34,MATCH('Indian Project'!$C5,'Int. Budget On-Off 3'!$AC$12:$AC$34,0),3)))) -> 0 | F5: =IF($R$3=1,INDEX('Int. Budget On-Off 1'!$AC$12:$AF$34,MATCH('Indian Project'!$C5,'Int. Budget On-Off 1'!$AC$12:$AC$34,0),4),IF($R$3=2,INDEX('Int. Budget On-Off 2'!$AC$12:$AF$34,MATCH('Indian Project'!$C5,'Int. Budget On-Off 2'!$AC$12:$AC$34,0),4),IF($R$3=3,INDEX('Int. Budget On-Off 3'!$AC$12:$AF$34,MATCH('Indian Project'!$C5,'Int. Budget On-Off 3'!$AC$12:$AC$34,0),4)))) -> 0 | I5: xI102 | J5: In - Acceptance preparation | K5: =IF($R$3=1,INDEX('Int. Budget On-Off 1'!$AG$12:$AJ$34,MATCH('Indian Project'!$I5,'Int. Budget On-Off 1'!$AG$12:$AG$34,0),3),IF($R$3=2,INDEX('Int. Budget On-Off 2'!$AG$12:$AJ$34,MATCH('Indian Project'!$I5,'Int. Budget On-Off 2'!$AG$12:$AG$34,0),3),IF($R$3=3,INDEX('Int. Budget On-Off 3'!$AG$12:$AJ$34,MATCH('Indian Project'!$I5,'Int. Budget On-Off 3'!$AG$12:$AG$34,0),3)))) -> 0 | L5: =IF($R$3=1,INDEX('Int. Budget On-Off 1'!$AG$12:$AJ$34,MATCH('Indian Project'!$I5,'Int. Budget On-Off 1'!$AG$12:$AG$34,0),4),IF($R$3=2,INDEX('Int. Budget On-Off 2'!$AG$12:$AJ$34,MATCH('Indian Project'!$I5,'Int. Budget On-Off 2'!$AG$12:$AG$34,0),4),IF($R$3=3,INDEX('Int. Budget On-Off 3'!$AG$12:$AJ$34,MATCH('Indian Project'!$I5,'Int. Budget On-Off 3'!$AG$12:$AG$34,0),4)))) -> 0 | P5: Global Budget without PPR | R5: =R4*0.9 -> 0
B6: Project | C6: xF10R | D6: Fr - Upstream Review | E6: =IF($R$3=1,INDEX('Int. Budget On-Off 1'!$AC$12:$AF$34,MATCH('Indian Project'!$C6,'Int. Budget On-Off 1'!$AC$12:$AC$34,0),3),IF($R$3=2,INDEX('Int. Budget On-Off 2'!$AC$12:$AF$34,MATCH('Indian Project'!$C6,'Int. Budget On-Off 2'!$AC$12:$AC$34,0),3),IF($R$3=3,INDEX('Int. Budget On-Off 3'!$AC$12:$AF$34,MATCH('Indian Project'!$C6,'Int. Budget On-Off 3'!$AC$12:$AC$34,0),3)))) -> 0 | F6: =IF($R$3=1,INDEX('Int. Budget On-Off 1'!$AC$12:$AF$34,MATCH('Indian Project'!$C6,'Int. Budget On-Off 1'!$AC$12:$AC$34,0),4),IF($R$3=2,INDEX('Int. Budget On-Off 2'!$AC$12:$AF$34,MATCH('Indian Project'!$C6,'Int. Budget On-Off 2'!$AC$12:$AC$34,0),4),IF($R$3=3,INDEX('Int. Budget On-Off 3'!$AC$12:$AF$34,MATCH('Indian Project'!$C6,'Int. Budget On-Off 3'!$AC$12:$AC$34,0),4)))) -> 0 | I6: xI105 | J6: In - SFD Acceptance | K6: =IF($R$3=1,INDEX('Int. Budget On-Off 1'!$AG$12:$AJ$34,MATCH('Indian Project'!$I6,'Int. Budget On-Off 1'!$AG$12:$AG$34,0),3),IF($R$3=2,INDEX('Int. Budget On-Off 2'!$AG$12:$AJ$34,MATCH('Indian Project'!$I6,'Int. Budget On-Off 2'!$AG$12:$AG$34,0),3),IF($R$3=3,INDEX('Int. Budget On-Off 3'!$AG$12:$AJ$34,MATCH('Indian Project'!$I6,'Int. Budget On-Off 3'!$AG$12:$AG$34,0),3)))) -> 0 | L6: =IF($R$3=1,INDEX('Int. Budget On-Off 1'!$AG$12:$AJ$34,MATCH('Indian Project'!$I6,'Int. Budget On-Off 1'!$AG$12:$AG$34,0),4),IF($R$3=2,INDEX('Int. Budget On-Off 2'!$AG$12:$AJ$34,MATCH('Indian Project'!$I6,'Int. Budget On-Off 2'!$AG$12:$AG$34,0),4),IF($R$3=3,INDEX('Int. Budget On-Off 3'!$AG$12:$AJ$34,MATCH('Indian Project'!$I6,'Int. Budget On-Off 3'!$AG$12:$AG$34,0),4)))) -> 0 | P6: Global Budget with PPR (Abacus ; sold to CAAGIS) | R6: 555
I7: xI106 | J7: In - SMT Acceptance | K7: =IF($R$3=1,INDEX('Int. Budget On-Off 1'!$AG$12:$AJ$34,MATCH('Indian Project'!$I7,'Int. Budget On-Off 1'!$AG$12:$AG$34,0),3),IF($R$3=2,INDEX('Int. Budget On-Off 2'!$AG$12:$AJ$34,MATCH('Indian Project'!$I7,'Int. Budget On-Off 2'!$AG$12:$AG$34,0),3),IF($R$3=3,INDEX('Int. Budget On-Off 3'!$AG$12:$AJ$34,MATCH('Indian Project'!$I7,'Int. Budget On-Off 3'!$AG$12:$AG$34,0),3)))) -> 0 | L7: =IF($R$3=1,INDEX('Int. Budget On-Off 1'!$AG$12:$AJ$34,MATCH('Indian Project'!$I7,'Int. Budget On-Off 1'!$AG$12:$AG$34,0),4),IF($R$3=2,INDEX('Int. Budget On-Off 2'!$AG$12:$AJ$34,MATCH('Indian Project'!$I7,'Int. Budget On-Off 2'!$AG$12:$AG$34,0),4),IF($R$3=3,INDEX('Int. Budget On-Off 3'!$AG$12:$AJ$34,MATCH('Indian Project'!$I7,'Int. Budget On-Off 3'!$AG$12:$AG$34,0),4)))) -> 0 | P7: Global Budget without PPR | R7: =R6*90% -> 0
I8: xI108 | J8: In - Doing development sheet | K8: =IF($R$3=1,INDEX('Int. Budget On-Off 1'!$AG$12:$AJ$34,MATCH('Indian Project'!$I8,'Int. Budget On-Off 1'!$AG$12:$AG$34,0),3),IF($R$3=2,INDEX('Int. Budget On-Off 2'!$AG$12:$AJ$34,MATCH('Indian Project'!$I8,'Int. Budget On-Off 2'!$AG$12:$AG$34,0),3),IF($R$3=3,INDEX('Int. Budget On-Off 3'!$AG$12:$AJ$34,MATCH('Indian Project'!$I8,'Int. Budget On-Off 3'!$AG$12:$AG$34,0),3)))) -> 0 | L8: =IF($R$3=1,INDEX('Int. Budget On-Off 1'!$AG$12:$AJ$34,MATCH('Indian Project'!$I8,'Int. Budget On-Off 1'!$AG$12:$AG$34,0),4),IF($R$3=2,INDEX('Int. Budget On-Off 2'!$AG$12:$AJ$34,MATCH('Indian Project'!$I8,'Int. Budget On-Off 2'!$AG$12:$AG$34,0),4),IF($R$3=3,INDEX('Int. Budget On-Off 3'!$AG$12:$AJ$34,MATCH('Indian Project'!$I8,'Int. Budget On-Off 3'!$AG$12:$AG$34,0),4)))) -> 0 | P8: Pre-integration budget to extract (negative) | R8: =(-R12-R13)*0.9 -> 0
A9: Development | B9: Project | C9: xF14A | D9: Fr - Param Acceptance Assistance | E9: =IF($R$3=1,INDEX('Int. Budget On-Off 1'!$AC$12:$AF$34,MATCH('Indian Project'!$C9,'Int. Budget On-Off 1'!$AC$12:$AC$34,0),3),IF($R$3=2,INDEX('Int. Budget On-Off 2'!$AC$12:$AF$34,MATCH('Indian Project'!$C9,'Int. Budget On-Off 2'!$AC$12:$AC$34,0),3),IF($R$3=3,INDEX('Int. Budget On-Off 3'!$AC$12:$AF$34,MATCH('Indian Project'!$C9,'Int. Budget On-Off 3'!$AC$12:$AC$34,0),3)))) -> 0 | F9: =IF($R$3=1,INDEX('Int. Budget On-Off 1'!$AC$12:$AF$34,MATCH('Indian Project'!$C9,'Int. Budget On-Off 1'!$AC$12:$AC$34,0),4),IF($R$3=2,INDEX('Int. Budget On-Off 2'!$AC$12:$AF$34,MATCH('Indian Project'!$C9,'Int. Budget On-Off 2'!$AC$12:$AC$34,0),4),IF($R$3=3,INDEX('Int. Budget On-Off 3'!$AC$12:$AF$34,MATCH('Indian Project'!$C9,'Int. Budget On-Off 3'!$AC$12:$AC$34,0),4)))) -> 0 | I9: xI140 | J9: in - Param Acceptance | K9: =IF($R$3=1,INDEX('Int. Budget On-Off 1'!$AG$12:$AJ$34,MATCH('Indian Project'!$I9,'Int. Budget On-Off 1'!$AG$12:$AG$34,0),3),IF($R$3=2,INDEX('Int. Budget On-Off 2'!$AG$12:$AJ$34,MATCH('Indian Project'!$I9,'Int. Budget On-Off 2'!$AG$12:$AG$34,0),3),IF($R$3=3,INDEX('Int. Budget On-Off 3'!$AG$12:$AJ$34,MATCH('Indian Project'!$I9,'Int. Budget On-Off 3'!$AG$12:$AG$34,0),3)))) -> 0 | L9: =IF($R$3=1,INDEX('Int. Budget On-Off 1'!$AG$12:$AJ$34,MATCH('Indian Project'!$I9,'Int. Budget On-Off 1'!$AG$12:$AG$34,0),4),IF($R$3=2,INDEX('Int. Budget On-Off 2'!$AG$12:$AJ$34,MATCH('Indian Project'!$I9,'Int. Budget On-Off 2'!$AG$12:$AG$34,0),4),IF($R$3=3,INDEX('Int. Budget On-Off 3'!$AG$12:$AJ$34,MATCH('Indian Project'!$I9,'Int. Budget On-Off 3'!$AG$12:$AG$34,0),4)))) -> 0 | P9: Global budget after Pre-integration budget | R9: =R7+R8 -> 0
B10: Project | C10: xF30A | D10: Fr - CUT Assistance | E10: =IF($R$3=1,INDEX('Int. Budget On-Off 1'!$AC$12:$AF$34,MATCH('Indian Project'!$C10,'Int. Budget On-Off 1'!$AC$12:$AC$34,0),3),IF($R$3=2,INDEX('Int. Budget On-Off 2'!$AC$12:$AF$34,MATCH('Indian Project'!$C10,'Int. Budget On-Off 2'!$AC$12:$AC$34,0),3),IF($R$3=3,INDEX('Int. Budget On-Off 3'!$AC$12:$AF$34,MATCH('Indian Project'!$C10,'Int. Budget On-Off 3'!$AC$12:$AC$34,0),3)))) -> 0 | F10: =IF($R$3=1,INDEX('Int. Budget On-Off 1'!$AC$12:$AF$34,MATCH('Indian Project'!$C10,'Int. Budget On-Off 1'!$AC$12:$AC$34,0),4),IF($R$3=2,INDEX('Int. Budget On-Off 2'!$AC$12:$AF$34,MATCH('Indian Project'!$C10,'Int. Budget On-Off 2'!$AC$12:$AC$34,0),4),IF($R$3=3,INDEX('Int. Budget On-Off 3'!$AC$12:$AF$34,MATCH('Indian Project'!$C10,'Int. Budget On-Off 3'!$AC$12:$AC$34,0),4)))) -> 0 | I10: xI3** | J10: In - CUT | K10: =IF($R$3=1,INDEX('Int. Budget On-Off 1'!$AG$12:$AJ$34,MATCH('Indian Project'!$I10,'Int. Budget On-Off 1'!$AG$12:$AG$34,0),3),IF($R$3=2,INDEX('Int. Budget On-Off 2'!$AG$12:$AJ$34,MATCH('Indian Project'!$I10,'Int. Budget On-Off 2'!$AG$12:$AG$34,0),3),IF($R$3=3,INDEX('Int. Budget On-Off 3'!$AG$12:$AJ$34,MATCH('Indian Project'!$I10,'Int. Budget On-Off 3'!$AG$12:$AG$34,0),3)))) -> 0 | L10: =IF($R$3=1,INDEX('Int. Budget On-Off 1'!$AG$12:$AJ$34,MATCH('Indian Project'!$I10,'Int. Budget On-Off 1'!$AG$12:$AG$34,0),4),IF($R$3=2,INDEX('Int. Budget On-Off 2'!$AG$12:$AJ$34,MATCH('Indian Project'!$I10,'Int. Budget On-Off 2'!$AG$12:$AG$34,0),4),IF($R$3=3,INDEX('Int. Budget On-Off 3'!$AG$12:$AJ$34,MATCH('Indian Project'!$I10,'Int. Budget On-Off 3'!$AG$12:$AG$34,0),4)))) -> 0 | M10: ='Development effort'!F24 -> 0
B11: Project | C11: xF30T | D11: Fr - CUT Other Tasks + Transl. | E11: =IF($R$3=1,INDEX('Int. Budget On-Off 1'!$AC$12:$AF$34,MATCH('Indian Project'!$C11,'Int. Budget On-Off 1'!$AC$12:$AC$34,0),3),IF($R$3=2,INDEX('Int. Budget On-Off 2'!$AC$12:$AF$34,MATCH('Indian Project'!$C11,'Int. Budget On-Off 2'!$AC$12:$AC$34,0),3),IF($R$3=3,INDEX('Int. Budget On-Off 3'!$AC$12:$AF$34,MATCH('Indian Project'!$C11,'Int. Budget On-Off 3'!$AC$12:$AC$34,0),3)))) -> 0 | F11: =IF($R$3=1,INDEX('Int. Budget On-Off 1'!$AC$12:$AF$34,MATCH('Indian Project'!$C11,'Int. Budget On-Off 1'!$AC$12:$AC$34,0),4),IF($R$3=2,INDEX('Int. Budget On-Off 2'!$AC$12:$AF$34,MATCH('Indian Project'!$C11,'Int. Budget On-Off 2'!$AC$12:$AC$34,0),4),IF($R$3=3,INDEX('Int. Budget On-Off 3'!$AC$12:$AF$34,MATCH('Indian Project'!$C11,'Int. Budget On-Off 3'!$AC$12:$AC$34,0),4)))) -> 0
B12: Project | C12: xF30R | D12: Fr - CUT review | E12: =IF($R$3=1,INDEX('Int. Budget On-Off 1'!$AC$12:$AF$34,MATCH('Indian Project'!$C12,'Int. Budget On-Off 1'!$AC$12:$AC$34,0),3),IF($R$3=2,INDEX('Int. Budget On-Off 2'!$AC$12:$AF$34,MATCH('Indian Project'!$C12,'Int. Budget On-Off 2'!$AC$12:$AC$34,0),3),IF($R$3=3,INDEX('Int. Budget On-Off 3'!$AC$12:$AF$34,MATCH('Indian Project'!$C12,'Int. Budget On-Off 3'!$AC$12:$AC$34,0),3)))) -> 0 | F12: =IF($R$3=1,INDEX('Int. Budget On-Off 1'!$AC$12:$AF$34,MATCH('Indian Project'!$C12,'Int. Budget On-Off 1'!$AC$12:$AC$34,0),4),IF($R$3=2,INDEX('Int. Budget On-Off 2'!$AC$12:$AF$34,MATCH('Indian Project'!$C12,'Int. Budget On-Off 2'!$AC$12:$AC$34,0),4),IF($R$3=3,INDEX('Int. Budget On-Off 3'!$AC$12:$AF$34,MATCH('Indian Project'!$C12,'Int. Budget On-Off 3'!$AC$12:$AC$34,0),4)))) -> 0 | P12: Fr - Pre-intergration (xnet) - PPR include | R12: 0
A13: Qualification | B13: Project | C13: xF50A | D13: Fr - Qualification Assistance | E13: =IF($R$3=1,INDEX('Int. Budget On-Off 1'!$AC$12:$AF$34,MATCH('Indian Project'!$C13,'Int. Budget On-Off 1'!$AC$12:$AC$34,0),3),IF($R$3=2,INDEX('Int. Budget On-Off 2'!$AC$12:$AF$34,MATCH('Indian Project'!$C13,'Int. Budget On-Off 2'!$AC$12:$AC$34,0),3),IF($R$3=3,INDEX('Int. Budget On-Off 3'!$AC$12:$AF$34,MATCH('Indian Project'!$C13,'Int. Budget On-Off 3'!$AC$12:$AC$34,0),3)))) -> 0 | F13: =IF($R$3=1,INDEX('Int. Budget On-Off 1'!$AC$12:$AF$34,MATCH('Indian Project'!$C13,'Int. Budget On-Off 1'!$AC$12:$AC$34,0),4),IF($R$3=2,INDEX('Int. Budget On-Off 2'!$AC$12:$AF$34,MATCH('Indian Project'!$C13,'Int. Budget On-Off 2'!$AC$12:$AC$34,0),4),IF($R$3=3,INDEX('Int. Budget On-Off 3'!$AC$12:$AF$34,MATCH('Indian Project'!$C13,'Int. Budget On-Off 3'!$AC$12:$AC$34,0),4)))) -> 0 | I13: xI500 | J13: In - Qualification | K13: =IF($R$3=1,INDEX('Int. Budget On-Off 1'!$AG$12:$AJ$34,MATCH('Indian Project'!$I13,'Int. Budget On-Off 1'!$AG$12:$AG$34,0),3),IF($R$3=2,INDEX('Int. Budget On-Off 2'!$AG$12:$AJ$34,MATCH('Indian Project'!$I13,'Int. Budget On-Off 2'!$AG$12:$AG$34,0),3),IF($R$3=3,INDEX('Int. Budget On-Off 3'!$AG$12:$AJ$34,MATCH('Indian Project'!$I13,'Int. Budget On-Off 3'!$AG$12:$AG$34,0),3)))) -> 0 | L13: =IF($R$3=1,INDEX('Int. Budget On-Off 1'!$AG$12:$AJ$34,MATCH('Indian Project'!$I13,'Int. Budget On-Off 1'!$AG$12:$AG$34,0),4),IF($R$3=2,INDEX('Int. Budget On-Off 2'!$AG$12:$AJ$34,MATCH('Indian Project'!$I13,'Int. Budget On-Off 2'!$AG$12:$AG$34,0),4),IF($R$3=3,INDEX('Int. Budget On-Off 3'!$AG$12:$AJ$34,MATCH('Indian Project'!$I13,'Int. Budget On-Off 3'!$AG$12:$AG$34,0),4)))) -> 0 | P13: In - Pre-intergration (xnet) - PPR include | R13: 0
B14: Project | C14: xF50T | D14: Fr - Qualification Other Tasks + Transl. | E14: =IF($R$3=1,INDEX('Int. Budget On-Off 1'!$AC$12:$AF$34,MATCH('Indian Project'!$C14,'Int. Budget On-Off 1'!$AC$12:$AC$34,0),3),IF($R$3=2,INDEX('Int. Budget On-Off 2'!$AC$12:$AF$34,MATCH('Indian Project'!$C14,'Int. Budget On-Off 2'!$AC$12:$AC$34,0),3),IF($R$3=3,INDEX('Int. Budget On-Off 3'!$AC$12:$AF$34,MATCH('Indian Project'!$C14,'Int. Budget On-Off 3'!$AC$12:$AC$34,0),3)))) -> 0 | F14: =IF($R$3=1,INDEX('Int. Budget On-Off 1'!$AC$12:$AF$34,MATCH('Indian Project'!$C14,'Int. Budget On-Off 1'!$AC$12:$AC$34,0),4),IF($R$3=2,INDEX('Int. Budget On-Off 2'!$AC$12:$AF$34,MATCH('Indian Project'!$C14,'Int. Budget On-Off 2'!$AC$12:$AC$34,0),4),IF($R$3=3,INDEX('Int. Budget On-Off 3'!$AC$12:$AF$34,MATCH('Indian Project'!$C14,'Int. Budget On-Off 3'!$AC$12:$AC$34,0),4)))) -> 0 | I14: xI501 | J14: In - Qualification defect fixing | K14: =IF($R$3=1,INDEX('Int. Budget On-Off 1'!$AG$12:$AJ$34,MATCH('Indian Project'!$I14,'Int. Budget On-Off 1'!$AG$12:$AG$34,0),3),IF($R$3=2,INDEX('Int. Budget On-Off 2'!$AG$12:$AJ$34,MATCH('Indian Project'!$I14,'Int. Budget On-Off 2'!$AG$12:$AG$34,0),3),IF($R$3=3,INDEX('Int. Budget On-Off 3'!$AG$12:$AJ$34,MATCH('Indian Project'!$I14,'Int. Budget On-Off 3'!$AG$12:$AG$34,0),3)))) -> 0 | L14: =IF($R$3=1,INDEX('Int. Budget On-Off 1'!$AG$12:$AJ$34,MATCH('Indian Project'!$I14,'Int. Budget On-Off 1'!$AG$12:$AG$34,0),4),IF($R$3=2,INDEX('Int. Budget On-Off 2'!$AG$12:$AJ$34,MATCH('Indian Project'!$I14,'Int. Budget On-Off 2'!$AG$12:$AG$34,0),4),IF($R$3=3,INDEX('Int. Budget On-Off 3'!$AG$12:$AJ$34,MATCH('Indian Project'!$I14,'Int. Budget On-Off 3'!$AG$12:$AG$34,0),4)))) -> 0
B15: Project | C15: xF50R | D15: Fr - Qualification Review | E15: =IF($R$3=1,INDEX('Int. Budget On-Off 1'!$AC$12:$AF$34,MATCH('Indian Project'!$C15,'Int. Budget On-Off 1'!$AC$12:$AC$34,0),3),IF($R$3=2,INDEX('Int. Budget On-Off 2'!$AC$12:$AF$34,MATCH('Indian Project'!$C15,'Int. Budget On-Off 2'!$AC$12:$AC$34,0),3),IF($R$3=3,INDEX('Int. Budget On-Off 3'!$AC$12:$AF$34,MATCH('Indian Project'!$C15,'Int. Budget On-Off 3'!$AC$12:$AC$34,0),3)))) -> 0 | F15: =IF($R$3=1,INDEX('Int. Budget On-Off 1'!$AC$12:$AF$34,MATCH('Indian Project'!$C15,'Int. Budget On-Off 1'!$AC$12:$AC$34,0),4),IF($R$3=2,INDEX('Int. Budget On-Off 2'!$AC$12:$AF$34,MATCH('Indian Project'!$C15,'Int. Budget On-Off 2'!$AC$12:$AC$34,0),4),IF($R$3=3,INDEX('Int. Budget On-Off 3'!$AC$12:$AF$34,MATCH('Indian Project'!$C15,'Int. Budget On-Off 3'!$AC$12:$AC$34,0),4)))) -> 0
A16: Pré-intégration | B16: Project | C16: xF600 | D16: Fr - Pre-intergration (xnet) | E16: =$R$12*0.9 -> 0 | F16: =$R$12*0.9 -> 0 | I16: xI600 | J16: In - Pre-intergration (xnet) | K16: =$R$13*0.9 -> 0 | L16: =$R$13*0.9 -> 0 | P16: Budget for Additional qualification test plan with PPR | R16: 0
A17: Acceptance testing | B17: Project | C17: xF70A | D17: Fr - Acceptance testing Assistance | E17: =IF($R$3=1,INDEX('Int. Budget On-Off 1'!$AC$12:$AF$34,MATCH('Indian Project'!$C17,'Int. Budget On-Off 1'!$AC$12:$AC$34,0),3),IF($R$3=2,INDEX('Int. Budget On-Off 2'!$AC$12:$AF$34,MATCH('Indian Project'!$C17,'Int. Budget On-Off 2'!$AC$12:$AC$34,0),3),IF($R$3=3,INDEX('Int. Budget On-Off 3'!$AC$12:$AF$34,MATCH('Indian Project'!$C17,'Int. Budget On-Off 3'!$AC$12:$AC$34,0),3)))) -> 0 | F17: =IF($R$3=1,INDEX('Int. Budget On-Off 1'!$AC$12:$AF$34,MATCH('Indian Project'!$C17,'Int. Budget On-Off 1'!$AC$12:$AC$34,0),4),IF($R$3=2,INDEX('Int. Budget On-Off 2'!$AC$12:$AF$34,MATCH('Indian Project'!$C17,'Int. Budget On-Off 2'!$AC$12:$AC$34,0),4),IF($R$3=3,INDEX('Int. Budget On-Off 3'!$AC$12:$AF$34,MATCH('Indian Project'!$C17,'Int. Budget On-Off 3'!$AC$12:$AC$34,0),4)))) -> 0 | I17: xI700 | J17: In - Acceptance testing (Analyse) | K17: =IF($R$3=1,INDEX('Int. Budget On-Off 1'!$AG$12:$AJ$34,MATCH('Indian Project'!$I17,'Int. Budget On-Off 1'!$AG$12:$AG$34,0),3),IF($R$3=2,INDEX('Int. Budget On-Off 2'!$AG$12:$AJ$34,MATCH('Indian Project'!$I17,'Int. Budget On-Off 2'!$AG$12:$AG$34,0),3),IF($R$3=3,INDEX('Int. Budget On-Off 3'!$AG$12:$AJ$34,MATCH('Indian Project'!$I17,'Int. Budget On-Off 3'!$AG$12:$AG$34,0),3)))) -> 0 | L17: =IF($R$3=1,INDEX('Int. Budget On-Off 1'!$AG$12:$AJ$34,MATCH('Indian Project'!$I17,'Int. Budget On-Off 1'!$AG$12:$AG$34,0),4),IF($R$3=2,INDEX('Int. Budget On-Off 2'!$AG$12:$AJ$34,MATCH('Indian Project'!$I17,'Int. Budget On-Off 2'!$AG$12:$AG$34,0),4),IF($R$3=3,INDEX('Int. Budget On-Off 3'!$AG$12:$AJ$34,MATCH('Indian Project'!$I17,'Int. Budget On-Off 3'!$AG$12:$AG$34,0),4)))) -> 0
B18: Project | C18: xF70R | D18: Fr - Acceptance testing Review | E18: =IF($R$3=1,INDEX('Int. Budget On-Off 1'!$AC$12:$AF$34,MATCH('Indian Project'!$C18,'Int. Budget On-Off 1'!$AC$12:$AC$34,0),3),IF($R$3=2,INDEX('Int. Budget On-Off 2'!$AC$12:$AF$34,MATCH('Indian Project'!$C18,'Int. Budget On-Off 2'!$AC$12:$AC$34,0),3),IF($R$3=3,INDEX('Int. Budget On-Off 3'!$AC$12:$AF$34,MATCH('Indian Project'!$C18,'Int. Budget On-Off 3'!$AC$12:$AC$34,0),3)))) -> 0 | F18: =IF($R$3=1,INDEX('Int. Budget On-Off 1'!$AC$12:$AF$34,MATCH('Indian Project'!$C18,'Int. Budget On-Off 1'!$AC$12:$AC$34,0),4),IF($R$3=2,INDEX('Int. Budget On-Off 2'!$AC$12:$AF$34,MATCH('Indian Project'!$C18,'Int. Budget On-Off 2'!$AC$12:$AC$34,0),4),IF($R$3=3,INDEX('Int. Budget On-Off 3'!$AC$12:$AF$34,MATCH('Indian Project'!$C18,'Int. Budget On-Off 3'!$AC$12:$AC$34,0),4)))) -> 0 | I18: xI701 | J18: In - Acceptance testing (Bug) | K18: =IF($R$3=1,INDEX('Int. Budget On-Off 1'!$AG$12:$AJ$34,MATCH('Indian Project'!$I18,'Int. Budget On-Off 1'!$AG$12:$AG$34,0),3),IF($R$3=2,INDEX('Int. Budget On-Off 2'!$AG$12:$AJ$34,MATCH('Indian Project'!$I18,'Int. Budget On-Off 2'!$AG$12:$AG$34,0),3),IF($R$3=3,INDEX('Int. Budget On-Off 3'!$AG$12:$AJ$34,MATCH('Indian Project'!$I18,'Int. Budget On-Off 3'!$AG$12:$AG$34,0),3)))) -> 0 | L18: =IF($R$3=1,INDEX('Int. Budget On-Off 1'!$AG$12:$AJ$34,MATCH('Indian Project'!$I18,'Int. Budget On-Off 1'!$AG$12:$AG$34,0),4),IF($R$3=2,INDEX('Int. Budget On-Off 2'!$AG$12:$AJ$34,MATCH('Indian Project'!$I18,'Int. Budget On-Off 2'!$AG$12:$AG$34,0),4),IF($R$3=3,INDEX('Int. Budget On-Off 3'!$AG$12:$AJ$34,MATCH('Indian Project'!$I18,'Int. Budget On-Off 3'!$AG$12:$AG$34,0),4)))) -> 0 | P18: Budget for acceptance testing changes with PPR | R18: 0
B19: Project | C19: xF70T | D19: Fr - Acceptance testing Other Tasks + Transl. | E19: =IF($R$3=1,INDEX('Int. Budget On-Off 1'!$AC$12:$AF$34,MATCH('Indian Project'!$C19,'Int. Budget On-Off 1'!$AC$12:$AC$34,0),3),IF($R$3=2,INDEX('Int. Budget On-Off 2'!$AC$12:$AF$34,MATCH('Indian Project'!$C19,'Int. Budget On-Off 2'!$AC$12:$AC$34,0),3),IF($R$3=3,INDEX('Int. Budget On-Off 3'!$AC$12:$AF$34,MATCH('Indian Project'!$C19,'Int. Budget On-Off 3'!$AC$12:$AC$34,0),3)))) -> 0 | F19: =IF($R$3=1,INDEX('Int. Budget On-Off 1'!$AC$12:$AF$34,MATCH('Indian Project'!$C19,'Int. Budget On-Off 1'!$AC$12:$AC$34,0),4),IF($R$3=2,INDEX('Int. Budget On-Off 2'!$AC$12:$AF$34,MATCH('Indian Project'!$C19,'Int. Budget On-Off 2'!$AC$12:$AC$34,0),4),IF($R$3=3,INDEX('Int. Budget On-Off 3'!$AC$12:$AF$34,MATCH('Indian Project'!$C19,'Int. Budget On-Off 3'!$AC$12:$AC$34,0),4)))) -> 0 | I19: xI702 | J19: In - Acceptance testing (changes) | K19: =IF($R$3=1,INDEX('Int. Budget On-Off 1'!$AG$12:$AJ$34,MATCH('Indian Project'!$I19,'Int. Budget On-Off 1'!$AG$12:$AG$34,0),3),IF($R$3=2,INDEX('Int. Budget On-Off 2'!$AG$12:$AJ$34,MATCH('Indian Project'!$I19,'Int. Budget On-Off 2'!$AG$12:$AG$34,0),3),IF($R$3=3,INDEX('Int. Budget On-Off 3'!$AG$12:$AJ$34,MATCH('Indian Project'!$I19,'Int. Budget On-Off 3'!$AG$12:$AG$34,0),3)))) -> 0 | L19: =IF($R$3=1,INDEX('Int. Budget On-Off 1'!$AG$12:$AJ$34,MATCH('Indian Project'!$I19,'Int. Budget On-Off 1'!$AG$12:$AG$34,0),4),IF($R$3=2,INDEX('Int. Budget On-Off 2'!$AG$12:$AJ$34,MATCH('Indian Project'!$I19,'Int. Budget On-Off 2'!$AG$12:$AG$34,0),4),IF($R$3=3,INDEX('Int. Budget On-Off 3'!$AG$12:$AJ$34,MATCH('Indian Project'!$I19,'Int. Budget On-Off 3'!$AG$12:$AG$34,0),4)))) -> 0
B20: Project | C20: xF71R | D20: Fr - Documentation Review | E20: =IF($R$3=1,INDEX('Int. Budget On-Off 1'!$AC$12:$AF$34,MATCH('Indian Project'!$C20,'Int. Budget On-Off 1'!$AC$12:$AC$34,0),3),IF($R$3=2,INDEX('Int. Budget On-Off 2'!$AC$12:$AF$34,MATCH('Indian Project'!$C20,'Int. Budget On-Off 2'!$AC$12:$AC$34,0),3),IF($R$3=3,INDEX('Int. Budget On-Off 3'!$AC$12:$AF$34,MATCH('Indian Project'!$C20,'Int. Budget On-Off 3'!$AC$12:$AC$34,0),3)))) -> 0 | F20: =IF($R$3=1,INDEX('Int. Budget On-Off 1'!$AC$12:$AF$34,MATCH('Indian Project'!$C20,'Int. Budget On-Off 1'!$AC$12:$AC$34,0),4),IF($R$3=2,INDEX('Int. Budget On-Off 2'!$AC$12:$AF$34,MATCH('Indian Project'!$C20,'Int. Budget On-Off 2'!$AC$12:$AC$34,0),4),IF($R$3=3,INDEX('Int. Budget On-Off 3'!$AC$12:$AF$34,MATCH('Indian Project'!$C20,'Int. Budget On-Off 3'!$AC$12:$AC$34,0),4)))) -> 0 | I20: xI710 | J20: In - Documentation | K20: =IF($R$3=1,INDEX('Int. Budget On-Off 1'!$AG$12:$AJ$34,MATCH('Indian Project'!$I20,'Int. Budget On-Off 1'!$AG$12:$AG$34,0),3),IF($R$3=2,INDEX('Int. Budget On-Off 2'!$AG$12:$AJ$34,MATCH('Indian Project'!$I20,'Int. Budget On-Off 2'!$AG$12:$AG$34,0),3),IF($R$3=3,INDEX('Int. Budget On-Off 3'!$AG$12:$AJ$34,MATCH('Indian Project'!$I20,'Int. Budget On-Off 3'!$AG$12:$AG$34,0),3)))) -> 0 | L20: =IF($R$3=1,INDEX('Int. Budget On-Off 1'!$AG$12:$AJ$34,MATCH('Indian Project'!$I20,'Int. Budget On-Off 1'!$AG$12:$AG$34,0),4),IF($R$3=2,INDEX('Int. Budget On-Off 2'!$AG$12:$AJ$34,MATCH('Indian Project'!$I20,'Int. Budget On-Off 2'!$AG$12:$AG$34,0),4),IF($R$3=3,INDEX('Int. Budget On-Off 3'!$AG$12:$AJ$34,MATCH('Indian Project'!$I20,'Int. Budget On-Off 3'!$AG$12:$AG$34,0),4)))) -> 0 | M20: ='Development effort'!E23 -> 0
A21: Management | B21: Project | C21: xF130 | D21: Fr - Project Leader | E21: =IF($R$3=1,INDEX('Int. Budget On-Off 1'!$AC$12:$AF$34,MATCH('Indian Project'!$C21,'Int. Budget On-Off 1'!$AC$12:$AC$34,0),3),IF($R$3=2,INDEX('Int. Budget On-Off 2'!$AC$12:$AF$34,MATCH('Indian Project'!$C21,'Int. Budget On-Off 2'!$AC$12:$AC$34,0),3),IF($R$3=3,INDEX('Int. Budget On-Off 3'!$AC$12:$AF$34,MATCH('Indian Project'!$C21,'Int. Budget On-Off 3'!$AC$12:$AC$34,0),3)))) -> 0 | F21: =IF($R$3=1,INDEX('Int. Budget On-Off 1'!$AC$12:$AF$34,MATCH('Indian Project'!$C21,'Int. Budget On-Off 1'!$AC$12:$AC$34,0),4),IF($R$3=2,INDEX('Int. Budget On-Off 2'!$AC$12:$AF$34,MATCH('Indian Project'!$C21,'Int. Budget On-Off 2'!$AC$12:$AC$34,0),4),IF($R$3=3,INDEX('Int. Budget On-Off 3'!$AC$12:$AF$34,MATCH('Indian Project'!$C21,'Int. Budget On-Off 3'!$AC$12:$AC$34,0),4)))) -> 0 | I21: xI130 | J21: In - Project Leader | K21: =IF($R$3=1,INDEX('Int. Budget On-Off 1'!$AG$12:$AJ$34,MATCH('Indian Project'!$I21,'Int. Budget On-Off 1'!$AG$12:$AG$34,0),3),IF($R$3=2,INDEX('Int. Budget On-Off 2'!$AG$12:$AJ$34,MATCH('Indian Project'!$I21,'Int. Budget On-Off 2'!$AG$12:$AG$34,0),3),IF($R$3=3,INDEX('Int. Budget On-Off 3'!$AG$12:$AJ$34,MATCH('Indian Project'!$I21,'Int. Budget On-Off 3'!$AG$12:$AG$34,0),3)))) -> 0 | L21: =IF($R$3=1,INDEX('Int. Budget On-Off 1'!$AG$12:$AJ$34,MATCH('Indian Project'!$I21,'Int. Budget On-Off 1'!$AG$12:$AG$34,0),4),IF($R$3=2,INDEX('Int. Budget On-Off 2'!$AG$12:$AJ$34,MATCH('Indian Project'!$I21,'Int. Budget On-Off 2'!$AG$12:$AG$34,0),4),IF($R$3=3,INDEX('Int. Budget On-Off 3'!$AG$12:$AJ$34,MATCH('Indian Project'!$I21,'Int. Budget On-Off 3'!$AG$12:$AG$34,0),4)))) -> 0
A22: Transversal | B22: Version | D22: Global Project Manager | E22: =IF($R$3=1,'Int. Budget On-Off 1'!$AE$29*27%,IF($R$3=2,'Int. Budget On-Off 2'!$AE$29*27%,IF($R$3=3,'Int. Budget On-Off 3'!$AE$29*27%))) -> 0 | F22: =IF($R$3=1,'Int. Budget On-Off 1'!$AF$29*30%,IF($R$3=2,'Int. Budget On-Off 2'!$AF$29*30%,IF($R$3=3,'Int. Budget On-Off 3'!$AF$29*30%))) -> 0 | G22: =F22 -> 0 | I22: 0I002 | J22: Project Manager Off Team | K22: =IF($R$3=1,INDEX('Int. Budget On-Off 1'!$AG$12:$AJ$34,MATCH('Indian Project'!$I22,'Int. Budget On-Off 1'!$AG$12:$AG$34,0),3),IF($R$3=2,INDEX('Int. Budget On-Off 2'!$AG$12:$AJ$34,MATCH('Indian Project'!$I22,'Int. Budget On-Off 2'!$AG$12:$AG$34,0),3),IF($R$3=3,INDEX('Int. Budget On-Off 3'!$AG$12:$AJ$34,MATCH('Indian Project'!$I22,'Int. Budget On-Off 3'!$AG$12:$AG$34,0),3)))) -> 0 | L22: =IF($R$3=1,INDEX('Int. Budget On-Off 1'!$AG$12:$AJ$34,MATCH('Indian Project'!$I22,'Int. Budget On-Off 1'!$AG$12:$AG$34,0),4),IF($R$3=2,INDEX('Int. Budget On-Off 2'!$AG$12:$AJ$34,MATCH('Indian Project'!$I22,'Int. Budget On-Off 2'!$AG$12:$AG$34,0),4),IF($R$3=3,INDEX('Int. Budget On-Off 3'!$AG$12:$AJ$34,MATCH('Indian Project'!$I22,'Int. Budget On-Off 3'!$AG$12:$AG$34,0),4)))) -> 0 | M22: =L22 -> 0
B23: Version | D23: Project Manager | E23: =IF($R$3=1,'Int. Budget On-Off 1'!$AE$29*73%,IF($R$3=2,'Int. Budget On-Off 2'!$AE$29*73%,IF($R$3=3,'Int. Budget On-Off 3'!$AE$29*73%))) -> 0 | F23: =IF($R$3=1,'Int. Budget On-Off 1'!$AF$29*70%,IF($R$3=2,'Int. Budget On-Off 2'!$AF$29*70%,IF($R$3=3,'Int. Budget On-Off 3'!$AF$29*70%))) -> 0 | G23: =F23 -> 0 | I23: 0I003 | J23: Project Management Effort Off Team | K23: =IF($R$3=1,INDEX('Int. Budget On-Off 1'!$AG$12:$AJ$34,MATCH('Indian Project'!$I23,'Int. Budget On-Off 1'!$AG$12:$AG$34,0),3),IF($R$3=2,INDEX('Int. Budget On-Off 2'!$AG$12:$AJ$34,MATCH('Indian Project'!$I23,'Int. Budget On-Off 2'!$AG$12:$AG$34,0),3),IF($R$3=3,INDEX('Int. Budget On-Off 3'!$AG$12:$AJ$34,MATCH('Indian Project'!$I23,'Int. Budget On-Off 3'!$AG$12:$AG$34,0),3)))) -> 0 | L23: =IF($R$3=1,INDEX('Int. Budget On-Off 1'!$AG$12:$AJ$34,MATCH('Indian Project'!$I23,'Int. Budget On-Off 1'!$AG$12:$AG$34,0),4),IF($R$3=2,INDEX('Int. Budget On-Off 2'!$AG$12:$AJ$34,MATCH('Indian Project'!$I23,'Int. Budget On-Off 2'!$AG$12:$AG$34,0),4),IF($R$3=3,INDEX('Int. Budget On-Off 3'!$AG$12:$AJ$34,MATCH('Indian Project'!$I23,'Int. Budget On-Off 3'!$AG$12:$AG$34,0),4)))) -> 0 | M23: =L23 -> 0
B24: Version | D24: Test Manager | E24: =IF($R$3=1,'Int. Budget On-Off 1'!$AE$31,IF($R$3=2,'Int. Budget On-Off 2'!$AE$31,IF($R$3=3,'Int. Budget On-Off 3'!$AE$31))) -> 0 | F24: =IF($R$3=1,'Int. Budget On-Off 1'!$AF$31,IF($R$3=2,'Int. Budget On-Off 2'!$AF$31,IF($R$3=3,'Int. Budget On-Off 3'!$AF$31))) -> 0 | G24: =F24 -> 0
B25: Version | D25: Deployment | E25: =IF($R$3=1,'Int. Budget On-Off 1'!$AE$32,IF($R$3=2,'Int. Budget On-Off 2'!$AE$32,IF($R$3=3,'Int. Budget On-Off 3'!$AE$32))) -> 0 | F25: =IF($R$3=1,'Int. Budget On-Off 1'!$AF$32,IF($R$3=2,'Int. Budget On-Off 2'!$AF$32,IF($R$3=3,'Int. Budget On-Off 3'!$AF$32))) -> 0 | G25: =F25 -> 0
B26: Version | D26: Technical Support | E26: =IF($R$3=1,'Int. Budget On-Off 1'!$AE$30,IF($R$3=2,'Int. Budget On-Off 2'!$AE$30,IF($R$3=3,'Int. Budget On-Off 3'!$AE$30))) -> 0 | F26: =IF($R$3=1,'Int. Budget On-Off 1'!$AF$30,IF($R$3=2,'Int. Budget On-Off 2'!$AF$30,IF($R$3=3,'Int. Budget On-Off 3'!$AF$30))) -> 0 | G26: =F26 -> 0
D27: TOTAL | E27: =SUM(E4:E26) -> 0 | F27: =SUM(F4:F26) -> 0 | G27: =SUM(G4:G26) -> 0 | J27: TOTAL | K27: =SUM(K4:K26) -> 0 | L27: =SUM(L4:L26) -> 0 | M27: =SUM(M4:M26) -> 0
D28: Controle Transversal (somme above) | E28: =SUM(E22:E26) -> 0 | F28: =SUM(F22:F26) -> 0 | J28: Contrôle (Internal Bubget) | K28: =IF($R$3=1,'Int. Budget On-Off 1'!$S$38+'Int. Budget On-Off 1'!AN38,IF($R$3=2,'Int. Budget On-Off 2'!$S$38+'Int. Budget On-Off 2'!AN38,IF($R$3=3,'Int. Budget On-Off 3'!$S$38+'Int. Budget On-Off 3'!AN38)))+K16 -> 0 | L28: =IF($R$3=1,'Int. Budget On-Off 1'!$T$38+'Int. Budget On-Off 1'!AO38,IF($R$3=2,'Int. Budget On-Off 2'!$T$38+'Int. Budget On-Off 2'!AO38,IF($R$3=3,'Int. Budget On-Off 3'!$T$38+'Int. Budget On-Off 3'!AO38)))+L16 -> 0
D29: Controle Transversal (Internal Bubget) | E29: =IF($R$3=1,'Int. Budget On-Off 1'!$O$31+'Int. Budget On-Off 1'!$O$32+'Int. Budget On-Off 1'!$O$33+'Int. Budget On-Off 1'!$O$34+'Int. Budget On-Off 1'!$O$36+'Int. Budget On-Off 1'!$O$37+'Int. Budget On-Off 1'!AL33,IF($R$3=2,'Int. Budget On-Off 2'!$O$31+'Int. Budget On-Off 2'!$O$32+'Int. Budget On-Off 2'!$O$33+'Int. Budget On-Off 2'!$O$34+'Int. Budget On-Off 2'!$O$36+'Int. Budget On-Off 2'!$O$37+'Int. Budget On-Off 2'!AL33,IF($R$3=3,'Int. Budget On-Off 3'!$O$31+'Int. Budget On-Off 3'!$O$32+'Int. Budget On-Off 3'!$O$33+'Int. Budget On-Off 3'!$O$34+'Int. Budget On-Off 3'!$O$36+'Int. Budget On-Off 3'!$O$37+'Int. Budget On-Off 3'!AL33))) -> 0 | F29: =IF($R$3=1,'Int. Budget On-Off 1'!$P$31+'Int. Budget On-Off 1'!$P$32+'Int. Budget On-Off 1'!$P$33+'Int. Budget On-Off 1'!$P$34+'Int. Budget On-Off 1'!$P$36+'Int. Budget On-Off 1'!$P$37+'Int. Budget On-Off 1'!AM33,IF($R$3=2,'Int. Budget On-Off 2'!$P$31+'Int. Budget On-Off 2'!$P$32+'Int. Budget On-Off 2'!$P$33+'Int. Budget On-Off 2'!$P$34+'Int. Budget On-Off 2'!$P$36+'Int. Budget On-Off 2'!$P$37+'Int. Budget On-Off 2'!AM33,IF($R$3=3,'Int. Budget On-Off 3'!$P$31+'Int. Budget On-Off 3'!$P$32+'Int. Budget On-Off 3'!$P$33+'Int. Budget On-Off 3'!$P$34+'Int. Budget On-Off 3'!$P$36+'Int. Budget On-Off 3'!$P$37+'Int. Budget On-Off 3'!AM33))) -> 0
A31: TOTAL Onshore + Offshore | E31: =E27+K27 -> 0 | F31: =F27+L27 -> 0 | G31: =G27+M27 -> 0
D32: Contrôle (Internal Bubget) | E32: ='Int. Budget On-Off 1'!E8+'Int. Budget On-Off 1'!AL38+'Int. Budget On-Off 1'!AN38 -> 0 | F32: =IF($R$3=1,'Int. Budget On-Off 1'!$P$38+'Int. Budget On-Off 1'!$T$38-'Int. Budget On-Off 1'!E6*90%+'Int. Budget On-Off 1'!AM38+'Int. Budget On-Off 1'!AO38,IF($R$3=2,'Int. Budget On-Off 2'!$P$38+'Int. Budget On-Off 2'!$T$38-'Int. Budget On-Off 2'!E6*90%+'Int. Budget On-Off 2'!AM38+'Int. Budget On-Off 2'!AO38,IF($R$3=3,'Int. Budget On-Off 3'!$P$38+'Int. Budget On-Off 3'!$T$38-'Int. Budget On-Off 3'!E6*90%+'Int. Budget On-Off 3'!AM38+'Int. Budget On-Off 3'!AO38))) -> 0

Sheet Development effort
A1: Development Sheet | B1: Development sheet description | C1: Team (France/India) | D1: Person in charge | E1: Development effort (days)
E2: CTD | F2: Coding Documentation DOP | G2: Tests | H2: Total
E3: 0 | F3: 0 | G3: 0 | H3: =SUM(E3:G3) -> 0
E4: 0 | F4: 0 | G4: 0 | H4: =SUM(E4:G4) -> 0
E5: 0 | F5: 0 | G5: 0 | H5: =SUM(E5:G5) -> 0
E6: 0 | F6: 0 | G6: 0 | H6: =SUM(E6:G6) -> 0
E7: 0 | F7: 0 | G7: 0 | H7: =SUM(E7:G7) -> 0
E8: 0 | F8: 0 | G8: 0 | H8: =SUM(E8:G8) -> 0
E9: 0 | F9: 0 | G9: 0 | H9: =SUM(E9:G9) -> 0
E10: 0 | F10: 0 | G10: 0 | H10: =SUM(E10:G10) -> 0
E11: 0 | F11: 0 | G11: 0 | H11: =SUM(E11:G11) -> 0
E12: 0 | F12: 0 | G12: 0 | H12: =SUM(E12:G12) -> 0
E13: 0 | F13: 0 | G13: 0 | H13: =SUM(E13:G13) -> 0
E14: 0 | F14: 0 | G14: 0 | H14: =SUM(E14:G14) -> 0
... E22: 0 | F22: 0 | G22: 0 | H22: =SUM(E22:G22) -> 0
E23: =SUM(E3:E22) -> 0 | F23: =SUM(F3:F22) -> 0 | G23: =SUM(G3:G22) -> 0 | H23: =SUM(H3:H22) -> 0
F24: =F23+G23 -> 0
A25: Remark :
A26: A development sheet corresponds to a feature (transaction, function...) and can be attached only to one project. However, if a program is identified in several project, it will be necessary to make a sheet by project and the effort can be optimized they are confided to the same person.

Sheet Int. Budget On-Off 1
A1: Internal Budget - Onshore / Offshore model (with acceptance delegation)
A3: Parameters / settings | E3: MD | AL3: Onshore Ratio | AN3: Offshore Ratio
A4: Global Budget with PPR (Abacus ; sold to CAAGIS) | E4: ='Indian Project'!R6 -> 0 | AH4: Budget for Additional qualification test plan with PPR | AI4: ='Indian Project'!R16 -> 0 | AK4: Qualification | AL4: 0.15 | AN4: 0.66
AH5: Budget for acceptance testing changes with PPR | AI5: ='Indian Project'!R18 -> 0 | AK5: Acceptance testing | AL5: 0.18 | AN5: 0.63
A6: Pre-integration budget to extract (negative) | E6: =-AF6-AF7 -> 0 | F6: Fill from French task or Indian task in fonction according to the team which execute Avanet Ingeration ====> see on the right | AC6: xF600 | AD6: Fr - Pre-intergration (xnet) | AF6: ='Indian Project'!R12 -> 0 | AK6: Management | AL6: 0.065 | AN6: 0.025
A7: Global budget after Pre-integration budget | E7: =E4+E6 -> 0 | AC7: xI600 | AD7: In - Pre-intergration (xnet) | AF7: ='Indian Project'!R13 -> 0 | AK7: Translation | AL7: 0 | AN7: 0
A8: Global budget after Pre-integration budget without PPR | E8: =E7*0.9 -> 0
A9: Maximum forecasted maximum effort Onshore + Offshore | E9: =P38+T38 -> 0
D10: =(E9+E41-E5+E43/2)/E4 -> 0 | E10: =E9/E8 -> 0 | G10: Budget in % | O10: Budget in PD
A11: Phase | B11: Activity Description | C11: Step | D11: % Distribution | E11: Indicative Budget | F11: Indicative budget -% considering CUT as 100% | G11: Indicative Rates Onshore on Budget sold | H11: % | I11: Indicative Rates Offshore on budget sold | J11: % | K11: Onshore Overhead on Budget sold | L11: % | M11: Offshore Overhead on Budget sold | N11: % | O11: Onshore budget sold | P11: Onshore forecasted maximum effort | Q11: % | R11: % considering CUT as 100% | S11: Offshore budget sold | T11: Offshore forecasted maximum effort | U11: % | V11: % considering CUT as 100% | W11: On+Offshore -% considering CUT as 100% | X11: Comment | AB11: Global task | AC11: Onshore SSP Activity Tasks | AE11: Initial Budget | AF11: Forecasted effort | AG11: Offshore SSP Activity Tasks | AI11: Initial Budget | AJ11: Forecasted effort
A12: Upstream | B12: Visibility before starting the version: | C12: 1 | D12: 0 | E12: Incl transversal | AB12: UPSTR | AC12: xF10A | AD12: Fr - Upstream Assistance | AE12: =($O$14+$O$15+$O$16+$O$17+$O$18+$O$19+$O$23+$O$26+$O$24)*60% -> 0 | AF12: =($P$14+$P$15+$P$16+$P$17+$P$18++$P$19+$P$23+$P$26+$P$24)*60% -> 0 | AG12: xI101 | AH12: In - Project presentation | AI12: =$S$14 -> 0 | AJ12: =$T$14 -> 0
B13: SMR acceptance of the version | C13: 1b | D13: 0 | E13: Incl transversal | AC13: xF10T | AD13: Fr - Upstream Other Tasks + Transl. | AE13: =($O$14+$O$15+$O$16+$O$17+$O$18+$O$23+$O$26+$O$24)*15% -> 0 | AF13: =($P$14+$P$15+$P$16+$P$17+$P$18+$P$23+$P$26+$P$24)*15% -> 0 | AG13: xI102 | AH13: In - Acceptance preparation | AI13: =$S$15 -> 0 | AJ13: =$T$15 -> 0
B14: Project presentation | C14: 2 | D14: 0.0045 | E14: =E$7*D14 -> 0 | F14: =E14/$E$22 -> 0 | G14: 0.0045 | H14: =G14/$G$38 -> 0 | K14: 0.0032 | L14: =K14/$K$38 -> 0 | M14: 0.001 | N14: =M14/$M$38 -> 0 | O14: =G14*$E$7 -> 0 | P14: =K14*$E$7+O14 -> 0 | Q14: =P14/$P$38 -> 0 | R14: =($R$22/$Q$22)*Q14 -> 0 | T14: =M14*$E$7+S14 -> 0 | U14: =T14/$T$38 -> 0 | V14: =($V$22/$U$22)*U14 -> 0 | W14: =(P14+T14)/($P$22+$T$22) -> 0 | AC14: xF10R | AD14: Fr - Upstream Review | AE14: =($O$14+$O$15+$O$16+$O$17+$O$18+$O$23+$O$26+$O$24)*25%+$O$19*40% -> 0 | AF14: =($P$14+$P$15+$P$16+$P$17+$P$18+$P$23+$P$26+$P$24)*25%+$P$19*40% -> 0 | AG14: xI105 | AH14: In - SFD Acceptance | AI14: =$S$18 -> 0 | AJ14: =$T$18 -> 0
B15: Offshore commitment on the project development and Offshore /Onshore preparation on acceptance Onshore preparation for its expertise to check Offshore acceptance balance sheet | C15: 3 | D15: 0.0045 | E15: =E$7*D15 -> 0 | F15: =E15/$E$22 -> 0 | I15: 0.0045 | J15: =I15/$I$38 -> 0 | K15: 0.004 | L15: =K15/$K$38 -> 0 | M15: 0.0045 | N15: =M15/$M$38 -> 0 | P15: =K15*$E$7+O15 -> 0 | Q15: =P15/$P$38 -> 0 | R15: =($R$22/$Q$22)*Q15 -> 0 | S15: =I15*$E$7 -> 0 | T15: =M15*$E$7+S15 -> 0 | U15: =T15/$T$38 -> 0 | V15: =($V$22/$U$22)*U15 -> 0 | W15: =(P15+T15)/($P$22+$T$22) -> 0 | AG15: xI106 | AH15: In - SMT Acceptance | AI15: =$S$26+$S$24 -> 0 | AJ15: =$T$26+$T$24 -> 0
B16: Project SFD Reception (surface checks) and translation prerequisit | C16: 4 | D16: 0.0018 | E16: =E$7*D16 -> 0 | F16: =E16/$E$22 -> 0 | G16: 0.0018 | H16: =G16/$G$38 -> 0 | K16: =0.12%+0.08% -> 0 | L16: =K16/$K$38 -> 0 | O16: =G16*$E$7 -> 0 | P16: =K16*$E$7+O16 -> 0 | Q16: =P16/$P$38 -> 0 | R16: =($R$22/$Q$22)*Q16 -> 0 | W16: =(P16+T16)/($P$22+$T$22) -> 0 | AG16: xI108 | AH16: In - Doing development sheet | AI16: =$S$19 -> 0 | AJ16: =$T$19 -> 0
B17: Pre-acceptance | C17: 4 | D17: 0.0067 | E17: =E$7*D17 -> 0 | F17: =E17/$E$22 -> 0 | G17: 0.0067 | H17: =G17/$G$38 -> 0 | K17: =0.236%-0.036% -> 0 | L17: =K17/$K$38 -> 0 | O17: =G17*$E$7 -> 0 | P17: =K17*$E$7+O17 -> 0 | Q17: =P17/$P$38 -> 0 | R17: =($R$22/$Q$22)*Q17 -> 0 | W17: =(P17+T17)/($P$22+$T$22) -> 0 | AB17: DEV | AC17: xF14A | AD17: Fr - Param Acceptance Assistance | AE17: =$O$25 -> 0 | AF17: =$P$25 -> 0
B18: DFS acceptance of the project | C18: 5 | D18: 0.023 | E18: =E$7*D18 -> 0 | F18: =E18/$E$22 -> 0 | I18: 0.0185 | J18: =I18/$I$38 -> 0 | K18: =0.32%+0.03% -> 0 | L18: =K18/$K$38 -> 0 | M18: =2.5%-1.5% -> 0 | N18: =M18/$M$38 -> 0 | O18: =G18*$E$7 -> 0 | P18: =K18*$E$7+O18 -> 0 | Q18: =P18/$P$38 -> 0 | R18: =($R$22/$Q$22)*Q18 -> 0 | S18: =I18*$E$7 -> 0 | T18: =M18*$E$7+S18 -> 0 | U18: =T18/$T$38 -> 0 | V18: =($V$22/$U$22)*U18 -> 0 | W18: =(P18+T18)/($P$22+$T$22) -> 0 | AC18: xF30A | AD18: Fr - CUT Assistance | AE18: =$O$22*30% -> 0 | AF18: =$P$22*30% -> 0 | AG18: xI140 | AH18: in - Param Acceptance | AI18: =$S$25 -> 0 | AJ18: =$T$25 -> 0
B19: Technical conception - Project development sheets | C19: 6 | D19: 0.027 | E19: =E$7*D19 -> 0 | F19: =E19/$E$22 -> 0 | G19: 0.0045 | H19: =G19/$G$38 -> 0 | I19: 0.018 | J19: =I19/$I$38 -> 0 | K19: =0.32%+0.03% -> 0 | L19: =K19/$K$38 -> 0 | M19: =4%-1% -> 0 | N19: =M19/$M$38 -> 0 | O19: =G19*$E$7 -> 0 | P19: =K19*$E$7+O19 -> 0 | Q19: =P19/$P$38 -> 0 | R19: =($R$22/$Q$22)*Q19 -> 0 | S19: =I19*$E$7 -> 0 | T19: =M19*$E$7+S19 -> 0 | U19: =T19/$T$38 -> 0 | V19: =($V$22/$U$22)*U19 -> 0 | W19: =(P19+T19)/($P$22+$T$22) -> 0 | AC19: xF30T | AD19: Fr - CUT Other Tasks + Transl. | AE19: =$O$20+$O$21 -> 0 | AF19: =$P$20+$P$21 -> 0 | AG19: xI3** | AH19: In - CUT | AI19: =$S$22 -> 0 | AJ19: =$T$22 -> 0
A20: Q & A | B20: Question/Response during the project development - Sopra's Question | C20: 7 | D20: 0 | E20: =E$7*D20 -> 0 | F20: =E20/$E$22 -> 0 | G20: =0.9%-0.55% -> 0 | H20: =G20/$G$38 -> 0 | K20: =0%+0.1% -> 0 | L20: =K20/$K$38 -> 0 | O20: =G20*$E$7 -> 0 | P20: =K20*$E$7+O20 -> 0 | Q20: =P20/$P$38 -> 0 | R20: =($R$22/$Q$22)*Q20 -> 0 | W20: =(P20+T20)/($P$22+$T$22) -> 0 | AC20: xF30R | AD20: Fr - CUT review | AE20: =$O$22*70% -> 0 | AF20: =$P$22*70% -> 0
B21: Question/Response during the project development - Caagis' question | C21: 7 | D21: 0.0045 | E21: =E$7*D21 -> 0 | F21: =E21/$E$22 -> 0 | G21: =0.45%-0.25% -> 0 | H21: =G21/$G$38 -> 0 | K21: =0%+0.1% -> 0 | L21: =K21/$K$38 -> 0 | O21: =G21*$E$7 -> 0 | P21: =K21*$E$7+O21 -> 0 | Q21: =P21/$P$38 -> 0 | R21: =($R$22/$Q$22)*Q21 -> 0 | W21: =(P21+T21)/($P$22+$T$22) -> 0 | AB21: QUAL | AC21: xF50A | AD21: Fr - Qualification Assistance | AE21: =$O$27*25%+AL25 -> 0 | AF21: =$P$27*25%+AM25 -> 0 | AG21: xI500 | AH21: In - Qualification | AI21: =$S$27*70%+AN25 -> 0 | AJ21: =$T$27*70%+AO25 -> 0
A22: CUT | B22: Coding and unit tests of the project | C22: 8 | D22: =32.4%-0.32% -> 0 | E22: =E$7*D22 -> 0 | F22: =E22/$E$22 -> 0 | G22: =4%+0.8% -> 0 | H22: =G22/$G$38 -> 0 | I22: =25.92%+1% -> 0 | J22: =I22/$I$38 -> 0 | K22: =1%-0.2% -> 0 | L22: =K22/$K$38 -> 0 | M22: =1.75%+4.25% -> 0 | N22: =M22/$M$38 -> 0 | O22: =G22*$E$7 -> 0 | P22: =K22*$E$7+O22 -> 0 | Q22: =P22/$P$38 -> 0 | R22: 1 | S22: =I22*$E$7 -> 0 | T22: =M22*$E$7+S22 -> 0 | U22: =T22/$T$38 -> 0 | V22: 1 | W22: =(P22+T22)/($P$22+$T$22) -> 0 | AC22: xF50T | AD22: Fr - Qualification Other Tasks + Transl. | AE22: =$O$27*20%+AL27 -> 0 | AF22: =$P$27*20%+AM27 -> 0
A23: SMT non valued | B23: Acceptance of unvalued SMTs of project | C23: 9 | D23: 0.0035 | E23: =E$7*D23 -> 0 | F23: =E23/$E$22 -> 0 | G23: =0.35% -> 0 | H23: =G23/$G$38 -> 0 | K23: 0 | L23: =K23/$K$38 -> 0 | O23: =G23*$E$7 -> 0 | P23: =K23*$E$7+O23 -> 0 | Q23: =P23/$P$38 -> 0 | R23: =($R$22/$Q$22)*Q23 -> 0 | W23: =(P23+T23)/($P$22+$T$22) -> 0 | AC23: xF50R | AD23: Fr - Qualification Review | AE23: =$O$27*55%+AL26 -> 0 | AF23: =$P$27*55%+AM26 -> 0 | AG23: xI501 | AH23: In - Qualification defect fixing | AI23: =$S$27*30%+AN27 -> 0 | AJ23: =$T$27*30%+AO27 -> 0 | AL23: Onshore | AN23: Offshore
B24: Acceptance of unvalued SMTs of the project | C24: 10 | D24: 0.01 | E24: =E$7*D24 -> 0 | F24: =E24/$E$22 -> 0 | I24: 0.01 | J24: =I24/$I$38 -> 0 | K24: =0.4% -> 0 | L24: =K24/$K$38 -> 0 | M24: 0 | N24: =M24/$M$38 -> 0 | P24: =K24*$E$7+O24 -> 0 | Q24: =P24/$P$38 -> 0 | R24: =($R$22/$Q$22)*Q24 -> 0 | S24: =I24*$E$7 -> 0 | T24: =M24*$E$7+S24 -> 0 | U24: =T24/$T$38 -> 0 | V24: =($V$22/$U$22)*U24 -> 0 | W24: =(P24+T24)/($P$22+$T$22) -> 0 | AL24: Initial Budget | AM24: Forecasted effort | AN24: Initial Budget | AO24: Forecasted effort
A25: Parameter | B25: Acceptance of the project's functional configuration (parameters) | C25: 10b | D25: 0.005 | E25: =E$7*D25 -> 0 | F25: =E25/$E$22 -> 0 | I25: 0.005 | J25: =I25/$I$38 -> 0 | K25: =0.08%+0.02% -> 0 | L25: =K25/$K$38 -> 0 | M25: 0 | N25: =M25/$M$38 -> 0 | P25: =K25*$E$7+O25 -> 0 | Q25: =P25/$P$38 -> 0 | R25: =($R$22/$Q$22)*Q25 -> 0 | S25: =I25*$E$7 -> 0 | T25: =M25*$E$7+S25 -> 0 | U25: =T25/$T$38 -> 0 | V25: =($V$22/$U$22)*U25 -> 0 | W25: =(P25+T25)/($P$22+$T$22) -> 0 | AB25: ACCEPT | AC25: xF70A | AD25: Fr - Acceptance testing Assistance | AE25: =$O$29*30%+AL29 -> 0 | AF25: =$P$29*30%+AM29 -> 0 | AG25: xI700 | AH25: In - Acceptance testing (Analyse) | AI25: =$S$29*50% -> 0 | AJ25: =$T$29*50% -> 0 | AL25: =$AI$4*$AL$4*25% -> 0 | AM25: =AL25+AN25*20% -> 0 | AN25: =$AI$4*$AN$4*70% -> 0 | AO25: =AN25/75% -> 0
A26: SMT valued | B26: Acceptance of valued SMTs of project and qualification preparation | C26: 11 | D26: 0.03 | E26: =E$7*D26 -> 0 | F26: =E26/$E$22 -> 0 | I26: =3%-1% -> 0 | J26: =I26/$I$38 -> 0 | K26: =0.32%-0.02% -> 0 | L26: =K26/$K$38 -> 0 | M26: 0 | N26: =M26/$M$38 -> 0 | P26: =K26*$E$7+O26 -> 0 | Q26: =P26/$P$38 -> 0 | R26: =($R$22/$Q$22)*Q26 -> 0 | S26: =I26*$E$7 -> 0 | T26: =M26*$E$7+S26 -> 0 | U26: =T26/$T$38 -> 0 | V26: =($V$22/$U$22)*U26 -> 0 | W26: =(P26+T26)/($P$22+$T$22) -> 0 | AC26: xF70R | AD26: Fr - Acceptance testing Review | AE26: =$O$29*60%+AL30 -> 0 | AF26: =$P$29*60%+AM30 -> 0 | AG26: xI701 | AH26: In - Acceptance testing (Bug) | AI26: =$S$29*50% -> 0 | AJ26: =$T$29*50% -> 0 | AL26: =$AI$4*$AL$4*55% -> 0 | AM26: =AL26+AN26*20% -> 0
A27: Qualification Testing | B27: Internal qualification of the version batch | C27: 12 | D27: 0.09 | E27: =E$7*D27 -> 0 | F27: =E27/$E$22 -> 0 | G27: =2.16% -> 0 | H27: =G27/$G$38 -> 0 | I27: 0.09 | J27: =I27/$I$38 -> 0 | K27: 0.02352 | L27: =K27/$K$38 -> 0 | M27: =1.5%+0.9% -> 0 | N27: =M27/$M$38 -> 0 | O27: =G27*$E$7 -> 0 | P27: =K27*$E$7+O27 -> 0 | Q27: =P27/$P$38 -> 0 | R27: =($R$22/$Q$22)*Q27 -> 0 | S27: =I27*$E$7 -> 0 | T27: =M27*$E$7+S27 -> 0 | U27: =T27/$T$38 -> 0 | V27: =($V$22/$U$22)*U27 -> 0 | W27: =(P27+T27)/($P$22+$T$22) -> 0 | AC27: xF70T | AD27: Fr - Acceptance testing Other Tasks + Transl. | AE27: =$O$29*10%+AL31 -> 0 | AF27: =$P$29*10%+AM31 -> 0 | AG27: xI702 | AH27: In - Acceptance testing (changes) | AI27: =AN29+AN30 -> 0 | AJ27: =AO29+AO30 -> 0 | AL27: =$AI$4*$AL$4*20% -> 0 | AM27: =AL27+AN27*20% -> 0 | AN27: =$AI$4*$AN$4*30% -> 0 | AO27: =AN27/75% -> 0
A28: Delivery | B28: Delivery of the material to CAAGIS | C28: 13 | E28: Incl technical support | AC28: xF71R | AD28: Fr - Documentation Review | AE28: =$O$30 -> 0 | AF28: =$P$30 -> 0 | AG28: xI710 | AH28: In - Documentation | AI28: =$S$30 -> 0 | AJ28: =$T$30 -> 0
A29: Acceptance testing | B29: CAAGIS acceptance test | C29: 14 | D29: 0.144 | E29: =E$7*D29 -> 0 | F29: =E29/$E$22 -> 0 | G29: 0.0288 | H29: =G29/$G$38 -> 0 | I29: 0.1152 | J29: =I29/$I$38 -> 0 | K29: =0.6%+3.84%-0.57% -> 0 | L29: =K29/$K$38 -> 0 | M29: =0%+2% -> 0 | N29: =M29/$M$38 -> 0 | O29: =G29*$E$7 -> 0 | P29: =K29*$E$7+O29 -> 0 | Q29: =P29/$P$38 -> 0 | R29: =($R$22/$Q$22)*Q29 -> 0 | S29: =I29*$E$7 -> 0 | T29: =M29*$E$7+S29 -> 0 | U29: =T29/$T$38 -> 0 | V29: =($V$22/$U$22)*U29 -> 0 | W29: =(P29+T29)/($P$22+$T$22) -> 0 | AB29: TRANS | AD29: Voir Transversal au global | AE29: =$O$31+$O$32+$O$36+AL33 -> 0 | AF29: =$P$31+$P$32+$P$36+AM33 -> 0 | AG29: xI130 | AH29: In - Project Leader | AI29: =$S$35+AN33 -> 0 | AJ29: =$S$35+$T$37+AO33 -> 0 | AL29: =$AI$5*$AL$5*30% -> 0 | AM29: =AL29+AN29*20% -> 0 | AN29: =$AI$5*$AN$5*50% -> 0 | AO29: =AN29/75% -> 0
A30: Documentation | B30: Project documentation and knowledge transfer towards Maintenance | C30: 15 | D30: 0.027 | E30: =E$7*D30 -> 0 | F30: =E30/$E$22 -> 0 | G30: 0.0054 | H30: =G30/$G$38 -> 0 | I30: 0.0216 | J30: =I30/$I$38 -> 0 | K30: =0.08%+0.02% -> 0 | L30: =K30/$K$38 -> 0 | M30: 0 | N30: =M30/$M$38 -> 0 | O30: =G30*$E$7 -> 0 | P30: =K30*$E$7+O30 -> 0 | Q30: =P30/$P$38 -> 0 | R30: =($R$22/$Q$22)*Q30 -> 0 | S30: =I30*$E$7 -> 0 | T30: =M30*$E$7+S30 -> 0 | U30: =T30/$T$38 -> 0 | V30: =($V$22/$U$22)*U30 -> 0 | W30: =(P30+T30)/($P$22+$T$22) -> 0 | AD30: Technical support | AE30: =$O$33 -> 0 | AF30: =$P$33 -> 0 | AL30: =$AI$5*$AL$5*60% -> 0 | AM30: =AL30+AN30*20% -> 0 | AN30: =$AI$5*$AN$5*50% -> 0 | AO30: =AN30/75% -> 0
A31: Transversal | B31: Global Project Manager | C31: 16 | D31: 0.0398 | E31: =E$7*D31 -> 0 | F31: =E31/$E$22 -> 0 | G31: =2.21%-0.21% -> 0 | H31: =G31/$G$38 -> 0 | I31: =1%+0.5%+0.21% -> 0 | J31: =I31/$I$38 -> 0 | K31: =1.996%-1.5% -> 0 | L31: =K31/$K$38 -> 0 | N31: =M31/$M$38 -> 0 | O31: =G31*$E$7 -> 0 | P31: =K31*$E$7+O31 -> 0 | Q31: =P31/$P$38 -> 0 | R31: =($R$22/$Q$22)*Q31 -> 0 | S31: =I31*$E$7 -> 0 | T31: =M31*$E$7+S31 -> 0 | U31: =T31/$T$38 -> 0 | V31: =($V$22/$U$22)*U31 -> 0 | W31: =(P31+T31)/($P$22+$T$22) -> 0 | AD31: Test manager | AE31: =$O$34 -> 0 | AF31: =$P$34 -> 0 | AG31: 901 | AH31: In - Operationnal risk (global version) | AI31: =$S$36 -> 0 | AJ31: =$T$36 -> 0 | AL31: =$AI$5*$AL$5*10% -> 0 | AM31: =AL31+AN31*20% -> 0
B32: Project Manager | C32: 16 | D32: 0.0788 | E32: =E$7*D32 -> 0 | F32: =E32/$E$22 -> 0 | G32: =6.5%-0.5% -> 0 | H32: =G32/$G$38 -> 0 | I32: =2.59%+0.5% -> 0 | J32: =I32/$I$38 -> 0 | K32: =3.34%-2.34% -> 0 | L32: =K32/$K$38 -> 0 | N32: =M32/$M$38 -> 0 | O32: =G32*$E$7 -> 0 | P32: =K32*$E$7+O32 -> 0 | Q32: =P32/$P$38 -> 0 | R32: =($R$22/$Q$22)*Q32 -> 0 | S32: =I32*$E$7 -> 0 | T32: =M32*$E$7+S32 -> 0 | U32: =T32/$T$38 -> 0 | V32: =($V$22/$U$22)*U32 -> 0 | W32: =(P32+T32)/($P$22+$T$22) -> 0 | AD32: Voir Transversal au global | AE32: =$O$37 -> 0 | AF32: =$P$37 -> 0 | AG32: 0I002 | AH32: Project Manager Off Team | AI32: =$S$32+$S$31+AN35 -> 0 | AJ32: =$T$32+$T$31+($T$35-$S$35)/3 -> 0
B33: Technical Support | C33: 16 | D33: 0.0344 | E33: =E$7*D33 -> 0 | F33: =E33/$E$22 -> 0 | G33: =3%-0.5% -> 0 | H33: =G33/$G$38 -> 0 | I33: 0 | J33: =I33/$I$38 -> 0 | K33: =0.08%+0.02% -> 0 | L33: =K33/$K$38 -> 0 | N33: =M33/$M$38 -> 0 | O33: =G33*$E$7 -> 0 | P33: =K33*$E$7+O33 -> 0 | Q33: =P33/$P$38 -> 0 | R33: =($R$22/$Q$22)*Q33 -> 0 | S33: =I33*$E$7 -> 0 | T33: =M33*$E$7+S33 -> 0 | U33: =T33/$T$38 -> 0 | V33: =($V$22/$U$22)*U33 -> 0 | W33: =(P33+T33)/($P$22+$T$22) -> 0 | AC33: xF130 | AD33: Fr - Project managment | AE33: =$O$35 -> 0 | AF33: =$P$35 -> 0 | AG33: 0I003 | AH33: Project Management Effort Off Team | AI33: 0 | AJ33: =($T$35-$S$35)*2/3 -> 0 | AL33: =$AI$4*$AL$6+$AI$5*$AL$6 -> 0 | AM33: =AL33+AN33*20% -> 0 | AN33: =$AI$4*$AN$6*75% -> 0 | AO33: =AN33/75% -> 0
B34: Test Manager | C34: 16 | D34: =1%+0.32% -> 0 | E34: =E$7*D34 -> 0 | F34: =E34/$E$22 -> 0 | G34: =1.32% -> 0 | H34: =G34/$G$38 -> 0 | I34: 0 | J34: =I34/$I$38 -> 0 | K34: =0.48%+0.02% -> 0 | L34: =K34/$K$38 -> 0 | N34: =M34/$M$38 -> 0 | O34: =G34*$E$7 -> 0 | P34: =K34*$E$7+O34 -> 0 | Q34: =P34/$P$38 -> 0 | R34: =($R$22/$Q$22)*Q34 -> 0 | S34: =I34*$E$7 -> 0 | T34: =M34*$E$7+S34 -> 0 | U34: =T34/$T$38 -> 0 | V34: =($V$22/$U$22)*U34 -> 0 | W34: =(P34+T34)/($P$22+$T$22) -> 0
B35: Offshore Management | C35: 16 | D35: 0.0225 | E35: =E$7*D35 -> 0 | F35: =E35/$E$22 -> 0 | I35: 0.0225 | J35: =I35/$I$38 -> 0 | M35: =6%-0.5%-0.21%-0.5% -> 0 | N35: =M35/$M$38 -> 0 | S35: =I35*$E$7 -> 0 | T35: =M35*$E$7+S35 -> 0 | U35: =T35/$T$38 -> 0 | V35: =($V$22/$U$22)*U35 -> 0 | W35: =(P35+T35)/($P$22+$T$22) -> 0 | AE35: =SUM(AE6:AE34) -> 0 | AF35: =SUM(AF6:AF34) -> 0 | AI35: =SUM(AI6:AI34) -> 0 | AJ35: =SUM(AJ5:AJ34) -> 0 | AL35: =$AI$4*$AL$7+$AI$5*$AL$7 -> 0 | AM35: =AL35+AN35*20% -> 0 | AN35: =$AI$4*$AN$6*25%+$AI$5*$AN$6 -> 0 | AO35: =AN35/75% -> 0
B36: Operationnal transversal risks
B37: Deployement and on-call duty for monitoring production | C37: 17 | D37: 0.009 | E37: =E$7*D37 -> 0 | F37: =E37/$E$22 -> 0 | G37: 0.009 | H37: =G37/$G$38 -> 0 | K37: 0 | L37: =K37/$K$38 -> 0 | O37: =G37*$E$7 -> 0 | P37: =K37*$E$7+O37 -> 0 | Q37: =P37/$P$38 -> 0 | R37: =($R$22/$Q$22)*Q37 -> 0 | W37: =(P37+T37)/($P$22+$T$22) -> 0
B38: Sub TOTAL | D38: =SUM(D12:D37) -> 0 | E38: =SUM(E12:E37) -> 0 | F38: =E38/$E$22 -> 0 | G38: =SUM(G12:G37) -> 0 | H38: =SUM(H13:H37) -> 0 | I38: =SUM(I12:I37) -> 0 | J38: =SUM(J13:J37) -> 0 | K38: =SUM(K12:K37) -> 0 | L38: =SUM(L13:L37) -> 0 | M38: =SUM(M12:M37) -> 0 | N38: =SUM(N13:N37) -> 0 | O38: =SUM(O12:O37) -> 0 | P38: =SUM(P12:P37) -> 0 | Q38: =SUM(Q13:Q37) -> 0 | R38: =SUM(R13:R37) -> 0 | S38: =SUM(S12:S37) -> 0 | T38: =SUM(T12:T37) -> 0 | U38: =SUM(U13:U37) -> 0 | V38: =SUM(V13:V37) -> 0 | W38: =(P38+T38)/($P$22+$T$22) -> 0 | X38: =W38/F38 -> 0 | AL38: =SUM(AL12:AL37) -> 0 | AM38: =SUM(AM12:AM37) -> 0 | AN38: =SUM(AN12:AN37) -> 0 | AO38: =SUM(AO12:AO37) -> 0
G39: =G38+I38 -> 0 | K39: =K38+M38 -> 0 | O39: =(P38-O38)/S38 -> 0 | S39: =T38/S38-1 -> 0 | X39: =S38/T38 -> 0 | Y39: Offshore Efficiency
G40: =G38/G39 -> 0 | I40: =I38/G39 -> 0 | K40: Target -> | O40: 0.2 | S40: 0.25 | X40: =O38/P38 -> 0 | Y40: Onshore Efficiency
O41: =O38/(O38+S38) -> 0 | P41: =P38/(P38+T38) -> 0 | S41: =S38/(O38+S38) -> 0 | T41: =T38/(P38+T38) -> 0 | X41: =(O38+S38+E41)/(P38+T38+E41) -> 0 | Y41: Global Efficiency with vicissitudes
...

Sheet Int. Budget On-Off 2
A1: Internal Budget - Onshore / Offshore model (From Dev sheet) | G1: Offshore involvement steps are 6, 8, 12, 14, 15, 16
A3: Parameters / settings | E3: MD | AL3: Onshore Ratio | AN3: Offshore Ratio
A4: Global Budget with PPR (Abacus ; sold to CAAGIS) | E4: ='Indian Project'!R6 -> 0 | AH4: Budget for Additional qualification test plan with PPR | AI4: ='Indian Project'!R16 -> 0 | AK4: Qualification | AL4: 0.15 | AN4: 0.66
A5: Global Budget without PPR | E5: =E4*90% -> 0 | AH5: Budget for acceptance testing changes with PPR | AI5: ='Indian Project'!R18 -> 0 | AK5: Acceptance testing | AL5: 0.18 | AN5: 0.63
A6: Pre-integration budget to extract (negative) | E6: =-AF6-AF7 -> 0 | F6: Fill from French task or Indian task in fonction according to the team which execute Avanet Ingeration ====> see on the right | AC6: xF600 | AD6: Fr - Pre-intergration (xnet) | AF6: ='Indian Project'!R12 -> 0 | AK6: Management | AL6: 0.065 | AN6: 0.025
A7: Global budget after Pre-integration budget | E7: =E4+E6 -> 0 | AC7: xI600 | AD7: In - Pre-intergration (xnet) | AF7: ='Indian Project'!R13 -> 0 | AK7: Translation | AL7: 0 | AN7: 0
A8: Global Budget without PPR | E8: =E7*0.9 -> 0
A9: Maximum forecasted maximum effort Onshore + Offshore | E9: =P38+T38 -> 0
D10: =(E9+E41-E5+E43/2)/E4 -> 0 | E10: =E9/E8 -> 0 | G10: Budget in % | O10: Budget in PD
A11: Phase | B11: Activity Description | C11: Step | D11: % Distribution | E11: Indicative Budget | F11: Indicative budget -% considering CUT as 100% | G11: Indicative Rates Onshore on Budget sold | H11: % | I11: Indicative Rates Offshore on budget sold | J11: % | K11: Onshore Overhead on Budget sold | L11: % | M11: Offshore Overhead on Budget sold | N11: % | O11: Onshore budget sold | P11: Onshore forecasted maximum effort | Q11: % | R11: % considering CUT as 100% | S11: Offshore budget sold | T11: Offshore forecasted maximum effort | U11: % | V11: % considering CUT as 100% | W11: On+Offshore -% considering CUT as 100% | X11: Comment | AB11: Global task | AC11: Onshore SSP Activity Tasks | AE11: Initial Budget | AF11: Forecasted effort | AG11: Offshore SSP Activity Tasks | AI11: Initial Budget | AJ11: Forecasted effort
A12: Upstream | B12: Visibility before starting the version: | C12: 1 | D12: 0 | E12: Incl transversal | AB12: UPSTR | AC12: xF10A | AD12: Fr - Upstream Assistance | AE12: =($O$14+$O$15+$O$16+$O$17+$O$18+$O$19+$O$23+$O$26+$O$24)*60% -> 0 | AF12: =($P$14+$P$15+$P$16+$P$17+$P$18++$P$19+$P$23+$P$26+$P$24)*60% -> 0 | AG12: xI101 | AH12: In - Project presentation | AI12: =$S$14 -> 0 | AJ12: =$T$14 -> 0
B13: SMR acceptance of the version | C13: 1b | D13: 0 | E13: Incl transversal | AC13: xF10T | AD13: Fr - Upstream Other Tasks + Transl. | AE13: =($O$14+$O$15+$O$16+$O$17+$O$18+$O$23+$O$26+$O$24)*15% -> 0 | AF13: =($P$14+$P$15+$P$16+$P$17+$P$18+$P$23+$P$26+$P$24)*15% -> 0 | AG13: xI102 | AH13: In - Acceptance preparation | AI13: =$S$15 -> 0 | AJ13: =$T$15 -> 0
B14: Project presentation | C14: 2 | D14: 0.0045 | E14: =E$7*D14 -> 0 | F14: =E14/$E$22 -> 0 | G14: 0.0045 | H14: =G14/$G$38 -> 0 | K14: 0.004 | L14: =K14/$K$38 -> 0 | M14: 0.01 | N14: =M14/$M$38 -> 0 | O14: =G14*$E$7 -> 0 | P14: =K14*$E$7+O14 -> 0 | Q14: =P14/$P$38 -> 0 | R14: =($R$22/$Q$22)*Q14 -> 0 | T14: =M14*$E$7+S14 -> 0 | U14: =T14/$T$38 -> 0 | V14: =($V$22/$U$22)*U14 -> 0 | W14: =(P14+T14)/($P$22+$T$22) -> 0 | AC14: xF10R | AD14: Fr - Upstream Review | AE14: =($O$14+$O$15+$O$16+$O$17+$O$18+$O$23+$O$26+$O$24)*25%+$O$19*40% -> 0 | AF14: =($P$14+$P$15+$P$16+$P$17+$P$18+$P$23+$P$26+$P$24)*25%+$P$19*40% -> 0 | AG14: xI105 | AH14: In - SFD Acceptance | AI14: =$S$18 -> 0 | AJ14: =$T$18 -> 0
B15: Onshore preparation to permit Offshore task from dev sheet | C15: 3 | D15: 0.0045 | E15: =E$7*D15 -> 0 | F15: =E15/$E$22 -> 0 | G15: 0.0045 | H15: =G15/$G$38 -> 0 | I15: 0 | J15: =I15/$I$38 -> 0 | K15: 0 | L15: =K15/$K$38 -> 0 | M15: 0 | N15: =M15/$M$38 -> 0 | O15: =G15*$E$7 -> 0 | P15: =K15*$E$7+O15 -> 0 | Q15: =P15/$P$38 -> 0 | R15: =($R$22/$Q$22)*Q15 -> 0 | S15: =I15*$E$7 -> 0 | T15: =M15*$E$7+S15 -> 0 | U15: =T15/$T$38 -> 0 | V15: =($V$22/$U$22)*U15 -> 0 | W15: =(P15+T15)/($P$22+$T$22) -> 0 | AG15: xI106 | AH15: In - SMT Acceptance | AI15: =$S$26+$S$24 -> 0 | AJ15: =$T$26+$T$24 -> 0
B16: Project SFD Reception (surface checks) and translation prerequisit | C16: 4 | D16: 0.0018 | E16: =E$7*D16 -> 0 | F16: =E16/$E$22 -> 0 | G16: 0.0018 | H16: =G16/$G$38 -> 0 | K16: 0.0015 | L16: =K16/$K$38 -> 0 | O16: =G16*$E$7 -> 0 | P16: =K16*$E$7+O16 -> 0 | Q16: =P16/$P$38 -> 0 | R16: =($R$22/$Q$22)*Q16 -> 0 | W16: =(P16+T16)/($P$22+$T$22) -> 0 | AG16: xI108 | AH16: In - Doing development sheet | AI16: =$S$19 -> 0 | AJ16: =$T$19 -> 0
